test_data/match.csv
_id,maker_order_id,price,product_id,sequence,side,size,taker_order_id,time,trade_id,type
5ad526e8e3ae7141c0171130,ec5c5f7b-d32b-43b7-b946-3adca972e022,8014.00000000,BTC-USD,5692403770,sell,0.00074934,5281588f-b333-4754-b0f3-2eb90ba1bf14,2018-04-16T22:42:51.576000Z,41762774,match
5ad526e8e3ae7141c0171132,8ffdf046-c9a0-4b9a-9828-4717ef098440,8014.00000000,BTC-USD,5692403772,sell,0.00378000,5281588f-b333-4754-b0f3-2eb90ba1bf14,2018-04-16T22:42:51.576000Z,41762775,match
5ad526e8e3ae7141c0171134,bef3d02b-9d15-4cb0-b9f2-843ea1c7a320,8014.00000000,BTC-USD,5692403774,sell,0.03947066,5281588f-b333-4754-b0f3-2eb90ba1bf14,2018-04-16T22:42:51.576000Z,41762776,match
5ad526f2e3ae7141c0171767,972ef644-9fac-4bc5-b505-e38be60a8372,8013.99000000,BTC-USD,5692406161,buy,0.00110000,706b1b43-f993-443b-ace7-6677f7d8cb74,2018-04-16T22:43:01.143000Z,41762777,match
5ad526f4e3ae7141c0171806,6189782c-a498-4cb0-b39a-a23f9dfa4289,8014.00000000,BTC-USD,5692406400,sell,0.00189000,314ff478-7507-400f-b088-769e87381a4d,2018-04-16T22:43:03.041000Z,41762778,match
5ad526f4e3ae7141c0171808,b8696c15-1ce0-43e8-a31a-ac2058955484,8014.00000000,BTC-USD,5692406402,sell,0.08001000,314ff478-7507-400f-b088-769e87381a4d,2018-04-16T22:43:03.041000Z,41762779,match
5ad526ffe3ae7141c0171c25,972ef644-9fac-4bc5-b505-e38be60a8372,8013.99000000,BTC-USD,5692407990,buy,0.02072445,7c2b2867-07d2-46cf-864a-7e83739f2238,2018-04-16T22:43:14.124000Z,41762780,match
5ad526ffe3ae7141c0171c27,1f138c54-0fb2-43a6-ac83-c56ea08eff74,8013.99000000,BTC-USD,5692407992,buy,0.00100000,7c2b2867-07d2-46cf-864a-7e83739f2238,2018-04-16T22:43:14.124000Z,41762781,match
5ad526ffe3ae7141c0171c29,15d01a4d-5c77-4d59-9f53-82c9ecb5d205,8013.99000000,BTC-USD,5692407994,buy,0.00955329,7c2b2867-07d2-46cf-864a-7e83739f2238,2018-04-16T22:43:14.124000Z,41762782,match
5ad526ffe3ae7141c0171c2b,9f1d5b9f-6406-4331-820d-de8f41b8ead0,8013.99000000,BTC-USD,5692407996,buy,0.00125000,7c2b2867-07d2-46cf-864a-7e83739f2238,2018-04-16T22:43:14.124000Z,41762783,match
5ad526ffe3ae7141c0171c2d,abf05c4a-be93-4648-afc7-26e877f4597e,8013.99000000,BTC-USD,5692407998,buy,0.00115000,7c2b2867-07d2-46cf-864a-7e83739f2238,2018-04-16T22:43:14.124000Z,41762784,match
5ad526ffe3ae7141c0171c2f,52e9784c-69d4-4a85-9707-00b5145eac46,8013.99000000,BTC-USD,5692408000,buy,0.99732226,7c2b2867-07d2-46cf-864a-7e83739f2238,2018-04-16T22:43:14.124000Z,41762785,match
5ad526ffe3ae7141c0171c54,52e9784c-69d4-4a85-9707-00b5145eac46,8013.99000000,BTC-USD,5692408054,buy,0.00267774,abb24bac-3b62-40b1-bb34-a9021a47d798,2018-04-16T22:43:14.541000Z,41762786,match
5ad526ffe3ae7141c0171c56,2717066c-d4c4-47a7-9ec9-7271f217f25f,8013.99000000,BTC-USD,5692408056,buy,0.00432226,abb24bac-3b62-40b1-bb34-a9021a47d798,2018-04-16T22:43:14.541000Z,41762787,match
5ad526ffe3ae7141c0171c6d,b8696c15-1ce0-43e8-a31a-ac2058955484,8014.00000000,BTC-USD,5692408093,sell,0.13999000,35f2f47f-6764-4494-a2db-a61eeb3ac21c,2018-04-16T22:43:14.826000Z,41762788,match
5ad526ffe3ae7141c0171c6f,976c956a-8543-47eb-9862-d3d3118ad66c,8014.00000000,BTC-USD,5692408095,sell,0.00265078,35f2f47f-6764-4494-a2db-a61eeb3ac21c,2018-04-16T22:43:14.826000Z,41762789,match
5ad526ffe3ae7141c0171c71,63d6ab10-db2a-4022-b116-e080a3b28327,8014.00000000,BTC-USD,5692408097,sell,0.32175922,35f2f47f-6764-4494-a2db-a61eeb3ac21c,2018-04-16T22:43:14.826000Z,41762790,match
5ad52700e3ae7141c0171c8e,2717066c-d4c4-47a7-9ec9-7271f217f25f,8013.99000000,BTC-USD,5692408140,buy,0.00100000,f253c9b7-57e7-4bb6-a3b5-2ec7d94b72d9,2018-04-16T22:43:14.891000Z,41762791,match
5ad52700e3ae7141c0171cc1,2717066c-d4c4-47a7-9ec9-7271f217f25f,8013.99000000,BTC-USD,5692408217,buy,0.00060263,ce15d128-246a-43c5-a4b2-a98c98dc2e04,2018-04-16T22:43:15.207000Z,41762792,match
5ad52700e3ae7141c0171cc3,7fe79f4e-4d8f-4708-ac46-dd66bf6a02c8,8013.99000000,BTC-USD,5692408219,buy,0.00039737,ce15d128-246a-43c5-a4b2-a98c98dc2e04,2018-04-16T22:43:15.207000Z,41762793,match
5ad52702e3ae7141c0171d49,7fe79f4e-4d8f-4708-ac46-dd66bf6a02c8,8013.99000000,BTC-USD,5692408418,buy,0.00100000,e143d1bf-22ce-480a-acd8-19d9da7b6aa8,2018-04-16T22:43:17.604000Z,41762794,match
5ad52706e3ae7141c0171e7f,63d6ab10-db2a-4022-b116-e080a3b28327,8014.00000000,BTC-USD,5692408888,sell,0.04578229,0567299f-9f98-48b1-8952-ae2dbee5b1c0,2018-04-16T22:43:21.433000Z,41762795,match
5ad52709e3ae7141c0171f16,7fe79f4e-4d8f-4708-ac46-dd66bf6a02c8,8013.99000000,BTC-USD,5692409111,buy,0.00050263,88fe6564-928e-4e97-9b50-c414971313ae,2018-04-16T22:43:24.306000Z,41762796,match
5ad52709e3ae7141c0171f18,ee70a804-77e7-4278-8945-9cbfac1a9173,8012.00000000,BTC-USD,5692409113,buy,0.00049737,88fe6564-928e-4e97-9b50-c414971313ae,2018-04-16T22:43:24.306000Z,41762797,match
5ad52709e3ae7141c0171f6b,ee70a804-77e7-4278-8945-9cbfac1a9173,8012.00000000,BTC-USD,5692409239,buy,0.00050263,59127c14-c66f-4059-b5b4-835c16533b9d,2018-04-16T22:43:24.576000Z,41762798,match
5ad52709e3ae7141c0171f6d,43f57566-6cda-4f59-acac-380933336281,8011.00000000,BTC-USD,5692409241,buy,0.00049737,59127c14-c66f-4059-b5b4-835c16533b9d,2018-04-16T22:43:24.576000Z,41762799,match
5ad5270ae3ae7141c0171fa5,43f57566-6cda-4f59-acac-380933336281,8011.00000000,BTC-USD,5692409325,buy,0.00050263,c2968ac5-8599-4185-959f-66a752a9f053,2018-04-16T22:43:24.989000Z,41762800,match
5ad5270ae3ae7141c0171fa7,8ae3f2d2-beb5-4f57-a32e-fd94718b5254,8011.00000000,BTC-USD,5692409327,buy,0.44549737,c2968ac5-8599-4185-959f-66a752a9f053,2018-04-16T22:43:24.989000Z,41762801,match
5ad5270ae3ae7141c0171faa,8ae3f2d2-beb5-4f57-a32e-fd94718b5254,8011.00000000,BTC-USD,5692409332,buy,0.00095163,4fb67d7f-f0cc-4b92-b2e5-56cc4fc0ea54,2018-04-16T22:43:24.992000Z,41762802,match
5ad5270ae3ae7141c0171fac,09218a10-f6cf-4997-ba67-1fc01b90367c,8010.00000000,BTC-USD,5692409334,buy,0.00100000,4fb67d7f-f0cc-4b92-b2e5-56cc4fc0ea54,2018-04-16T22:43:24.992000Z,41762803,match
5ad5270ae3ae7141c0171fae,2dd5677f-f390-4cf4-85a9-890ccd66eaab,8009.00000000,BTC-USD,5692409336,buy,0.00100000,4fb67d7f-f0cc-4b92-b2e5-56cc4fc0ea54,2018-04-16T22:43:24.992000Z,41762804,match
5ad5270ae3ae7141c0171fb0,8e520954-9c1e-4f56-9596-914c7292377d,8008.11000000,BTC-USD,5692409338,buy,0.00100000,4fb67d7f-f0cc-4b92-b2e5-56cc4fc0ea54,2018-04-16T22:43:24.992000Z,41762805,match
5ad5270ae3ae7141c0171fb2,e949b4a4-c65f-4557-9daf-ddcc0d32cb63,8008.00000000,BTC-USD,5692409340,buy,0.00100000,4fb67d7f-f0cc-4b92-b2e5-56cc4fc0ea54,2018-04-16T22:43:24.992000Z,41762806,match
5ad5270ae3ae7141c0171fb4,304835ad-3462-4f1a-b7db-191dfb7f8132,8007.00000000,BTC-USD,5692409342,buy,0.00100000,4fb67d7f-f0cc-4b92-b2e5-56cc4fc0ea54,2018-04-16T22:43:24.993000Z,41762807,match
5ad5270ae3ae7141c0171fb6,342353c1-724b-4951-b8ce-55c05b2cf5bc,8006.00000000,BTC-USD,5692409344,buy,0.00100000,4fb67d7f-f0cc-4b92-b2e5-56cc4fc0ea54,2018-04-16T22:43:24.993000Z,41762808,match
5ad5270ae3ae7141c0171fb8,86aab15c-8092-476e-b0cd-d613f5dbf3cc,8005.00000000,BTC-USD,5692409346,buy,0.00100000,4fb67d7f-f0cc-4b92-b2e5-56cc4fc0ea54,2018-04-16T22:43:24.993000Z,41762809,match
5ad5270ae3ae7141c0171fba,9c60a09e-24b6-436f-81b6-a770002f10c0,8004.95000000,BTC-USD,5692409348,buy,0.10000000,4fb67d7f-f0cc-4b92-b2e5-56cc4fc0ea54,2018-04-16T22:43:24.993000Z,41762810,match
5ad5270ae3ae7141c0171fbc,35fc1f2e-1524-4950-ad1f-83eda4203919,8004.01000000,BTC-USD,5692409350,buy,0.59204837,4fb67d7f-f0cc-4b92-b2e5-56cc4fc0ea54,2018-04-16T22:43:24.993000Z,41762811,match
5ad5270be3ae7141c01720c4,ff100741-01ee-4478-a7bd-6870d98ddef1,8006.23000000,BTC-USD,5692409746,sell,0.01310000,d7aa3f7a-b89a-476b-958e-839e2b2267e3,2018-04-16T22:43:26.123000Z,41762812,match
5ad52713e3ae7141c0172346,1f6e43a2-aac9-4833-a664-fb3d3b6b56ba,8006.23000000,BTC-USD,5692410712,buy,0.00174936,a2c54c3e-c01b-48cf-9b35-a3b570c2a4d4,2018-04-16T22:43:34.079000Z,41762813,match
5ad52713e3ae7141c0172348,ddb514d5-e6b4-4344-b154-8e7d96220120,8004.62000000,BTC-USD,5692410714,buy,0.09825064,a2c54c3e-c01b-48cf-9b35-a3b570c2a4d4,2018-04-16T22:43:34.079000Z,41762814,match
5ad52716e3ae7141c017257b,4174e8e6-a68f-424a-8b63-b76fac5206d6,8006.23000000,BTC-USD,5692411555,buy,0.37460000,7a948f29-db70-4b2a-aa4e-a1555c599284,2018-04-16T22:43:36.863000Z,41762815,match
